[2022-05-11 19:16:29,523: CRITICAL/MainProcess] Unrecoverable error: AccessRefused(403, 'ACCESS_REFUSED - Login was refused using authentication mechanism AMQPLAIN. For details see the broker logfile.', (0, 0), '')
Traceback (most recent call last):
  File "/usr/local/lib/python3.9/site-packages/celery/worker/worker.py", line 208, in start
    self.blueprint.start(self)
  File "/usr/local/lib/python3.9/site-packages/celery/bootsteps.py", line 119, in start
    step.start(parent)
  File "/usr/local/lib/python3.9/site-packages/celery/bootsteps.py", line 369, in start
    return self.obj.start()
  File "/usr/local/lib/python3.9/site-packages/celery/worker/consumer/consumer.py", line 318, in start
    blueprint.start(self)
  File "/usr/local/lib/python3.9/site-packages/celery/bootsteps.py", line 119, in start
    step.start(parent)
  File "/usr/local/lib/python3.9/site-packages/celery/worker/consumer/connection.py", line 23, in start
    c.connection = c.connect()
  File "/usr/local/lib/python3.9/site-packages/celery/worker/consumer/consumer.py", line 405, in connect
    conn = self.connection_for_read(heartbeat=self.amqheartbeat)
  File "/usr/local/lib/python3.9/site-packages/celery/worker/consumer/consumer.py", line 411, in connection_for_read
    return self.ensure_connected(
  File "/usr/local/lib/python3.9/site-packages/celery/worker/consumer/consumer.py", line 437, in ensure_connected
    conn = conn.ensure_connection(
  File "/usr/local/lib/python3.9/site-packages/kombu/connection.py", line 389, in ensure_connection
    self._ensure_connection(*args, **kwargs)
  File "/usr/local/lib/python3.9/site-packages/kombu/connection.py", line 441, in _ensure_connection
    return retry_over_time(
  File "/usr/local/lib/python3.9/site-packages/kombu/utils/functional.py", line 344, in retry_over_time
    return fun(*args, **kwargs)
  File "/usr/local/lib/python3.9/site-packages/kombu/connection.py", line 874, in _connection_factory
    self._connection = self._establish_connection()
  File "/usr/local/lib/python3.9/site-packages/kombu/connection.py", line 809, in _establish_connection
    conn = self.transport.establish_connection()
  File "/usr/local/lib/python3.9/site-packages/kombu/transport/pyamqp.py", line 130, in establish_connection
    conn.connect()
  File "/usr/local/lib/python3.9/site-packages/amqp/connection.py", line 320, in connect
    self.drain_events(timeout=self.connect_timeout)
  File "/usr/local/lib/python3.9/site-packages/amqp/connection.py", line 508, in drain_events
    while not self.blocking_read(timeout):
  File "/usr/local/lib/python3.9/site-packages/amqp/connection.py", line 514, in blocking_read
    return self.on_inbound_frame(frame)
  File "/usr/local/lib/python3.9/site-packages/amqp/method_framing.py", line 55, in on_frame
    callback(channel, method_sig, buf, None)
  File "/usr/local/lib/python3.9/site-packages/amqp/connection.py", line 520, in on_inbound_method
    return self.channels[channel_id].dispatch_method(
  File "/usr/local/lib/python3.9/site-packages/amqp/abstract_channel.py", line 145, in dispatch_method
    listener(*args)
  File "/usr/local/lib/python3.9/site-packages/amqp/connection.py", line 650, in _on_close
    raise error_for_code(reply_code, reply_text,
amqp.exceptions.AccessRefused: (0, 0): (403) ACCESS_REFUSED - Login was refused using authentication mechanism AMQPLAIN. For details see the broker logfile.
[2022-05-11 19:20:53,680: INFO/MainProcess] Connected to amqp://zoco:**@broker:5672//
[2022-05-11 19:20:53,688: INFO/MainProcess] mingle: searching for neighbors
[2022-05-11 19:20:54,711: INFO/MainProcess] mingle: sync with 3 nodes
[2022-05-11 19:20:54,711: INFO/MainProcess] mingle: sync complete
[2022-05-11 19:20:54,738: INFO/MainProcess] celery@6e5dea91a883 ready.
[2022-05-11 19:21:00,801: ERROR/MainProcess] Received unregistered task of type 'seller_center.get_seller_center_products'.
The message has been ignored and discarded.

Did you remember to import the module containing this task?
Or maybe you're using relative imports?

Please see
http://docs.celeryq.org/en/latest/internals/protocol.html
for more information.

The full contents of the message body was:
'[[1], {}, {"callbacks": null, "errbacks": null, "chain": null, "chord": null}]' (78b)
Traceback (most recent call last):
  File "/usr/local/lib/python3.9/site-packages/celery/worker/consumer/consumer.py", line 562, in on_task_received
    strategy = strategies[type_]
KeyError: 'seller_center.get_seller_center_products'
[2022-05-11 19:21:42,215: ERROR/MainProcess] Received unregistered task of type 'seller_center.get_seller_center_products'.
The message has been ignored and discarded.

Did you remember to import the module containing this task?
Or maybe you're using relative imports?

Please see
http://docs.celeryq.org/en/latest/internals/protocol.html
for more information.

The full contents of the message body was:
'[[1], {}, {"callbacks": null, "errbacks": null, "chain": null, "chord": null}]' (78b)
Traceback (most recent call last):
  File "/usr/local/lib/python3.9/site-packages/celery/worker/consumer/consumer.py", line 562, in on_task_received
    strategy = strategies[type_]
KeyError: 'seller_center.get_seller_center_products'
[2022-05-11 19:24:30,862: ERROR/MainProcess] Received unregistered task of type 'seller_center.get_seller_center_products'.
The message has been ignored and discarded.

Did you remember to import the module containing this task?
Or maybe you're using relative imports?

Please see
http://docs.celeryq.org/en/latest/internals/protocol.html
for more information.

The full contents of the message body was:
'[[1], {}, {"callbacks": null, "errbacks": null, "chain": null, "chord": null}]' (78b)
Traceback (most recent call last):
  File "/usr/local/lib/python3.9/site-packages/celery/worker/consumer/consumer.py", line 562, in on_task_received
    strategy = strategies[type_]
KeyError: 'seller_center.get_seller_center_products'
[2022-05-11 19:25:43,439: INFO/MainProcess] Connected to amqp://zoco:**@broker:5672//
[2022-05-11 19:25:43,446: INFO/MainProcess] mingle: searching for neighbors
[2022-05-11 19:25:44,468: INFO/MainProcess] mingle: sync with 3 nodes
[2022-05-11 19:25:44,469: INFO/MainProcess] mingle: sync complete
[2022-05-11 19:25:44,485: INFO/MainProcess] celery@6e5dea91a883 ready.
[2022-05-11 19:26:11,087: INFO/MainProcess] Connected to amqp://zoco:**@broker:5672//
[2022-05-11 19:26:11,096: INFO/MainProcess] mingle: searching for neighbors
[2022-05-11 19:26:12,117: INFO/MainProcess] mingle: sync with 3 nodes
[2022-05-11 19:26:12,117: INFO/MainProcess] mingle: sync complete
[2022-05-11 19:26:12,129: INFO/MainProcess] celery@6e5dea91a883 ready.
